Workbook

Sheet Data_Extraction_communication
A1: Paper_Name | B1: Paper_ID | C1: Exp_ID | D1: Treatment_ID | E1: Measure_ID | F1: Exp_ID_Cleaned | G1: ES_ID | H1: Title | I1: Authors | J1: Year | K1: Industry | L1: Venue | M1: Exp_Design | N1: Comp_Type | O1: Task_Desc | P1: Marketing_Task | Q1: Task_Data_Cleaned | R1: Task_Data_IsCategoric | S1: Task_Data_IsCode | T1: Task_Data_IsImage | U1: Task_Data_IsNumeric | V1: Task_Data_IsText | W1: Task_Data_IsVideo | X1: Task_Output | Y1: Task_Output_Cleaned | Z1: Task_Type | AA1: AI_Type | AB1: AI_Data_In | AC1: AI_Data_Out | AD1: AI_Type_Cleaned | AE1: Final_Decision | AF1: Division_Labor | AG1: Condition_Name | AH1: AI_Expl_Incl | AI1: AI_Conf_Incl | AJ1: AI_Expl_Type | AK1: Perf_Metric | AL1: Perf_Metric_Cleaned | AM1: Perf_Dir | AN1: N_Exp | AO1: N_Human | AP1: N_HumanAI | AQ1: Participant_Type | AR1: Participant_Type_2 | AS1: Participant_Source | AT1: Participant_Expert | AU1: Participant_Crowdworker | AV1: Avg_Perf_Human | AW1: Avg_Perf_AI | AX1: Avg_Perf_HumanAI | AY1: Avg_Perf_Human_Adj | AZ1: Avg_Perf_AI_Adj | BA1: Avg_Perf_HumanAI_Adj | BB1: Baseline | BC1: Avg_Perf_Baseline_Adj | BD1: Avg_Perf_Worse_Adj | BE1: Synergy | BF1: Sd_Perf_Human | BG1: Sd_Perf_AI | BH1: Sd_Perf_HumanAI | BI1: Sd_Perf_Baseline | BJ1: Sd_Perf_Worse | BK1: Est_ES | BL1: Notes | BM1: Notes_2
A2: Poursabzi-Sangdeh_2021 | B2: 5 | C2: 1 | D2: 1 | E2: 1 | F2: 5.1 | G2: 5.1.1.1 | H2: Manipulating and Measuring Model Interpretability | I2: Poursabzi-Sangdeh, Forough; Goldstein, Daniel G; Hofman, Jake M; Wortman Vaughan, Jennifer Wortman; Wallach, Hanna | J2: 2021 | K2: Business | L2: Proceedings of the 2021 CHI Conference on Human Factors in Computing Systems | M2: Mixed, Between-Subjects | N2: Independent Samples | O2: Predict housing prices | P2: =VLOOKUP(O2,Sheet3!$A$1:$B$22,2,0) -> Demand Forecasting | Q2: Numeric | R2: No | S2: No | T2: No | U2: Yes | V2: No | W2: No | X2: Numeric | Y2: Numeric | Z2: Decide | AA2: Shallow | AB2: Numeric | AC2: Numeric | AD2: Rule-Based | AE2: Human | AF2: No | AG2: HAI = BB-2 | AH2: No | AI2: No | AK2: Prediction Error | AL2: Error | AM2: Down | AN2: 1250 | AO2: 252 | AP2: 247 | AQ2: Crowdworkers | AR2: Crowdworkers | AS2: MTurk | AT2: No | AU2: Yes | AV2: 330555 | AW2: 180000 | AX2: 232267 | AY2: -330555 | AZ2: -180000 | BA2: -232267 | BB2: AI | BC2: -180000 | BD2: -330555 | BE2: 0 | BF2: 122515 | BG2: 0 | BH2: 56580 | BI2: 0 | BJ2: 122515 | BK2: No | BL2: HAI = BB-2
A3: Poursabzi-Sangdeh_2021 | B3: 5 | C3: 1 | D3: 2 | E3: 1 | F3: 5.1 | G3: 5.1.2.1 | H3: Manipulating and Measuring Model Interpretability | I3: Poursabzi-Sangdeh, Forough; Goldstein, Daniel G; Hofman, Jake M; Wortman Vaughan, Jennifer Wortman; Wallach, Hanna | J3: 2021 | K3: Business | L3: Proceedings of the 2021 CHI Conference on Human Factors in Computing Systems | M3: Mixed, Between-Subjects | N3: Independent Samples | O3: Predict housing prices | P3: =VLOOKUP(O3,Sheet3!$A$1:$B$22,2,0) -> Demand Forecasting | Q3: Numeric | R3: No | S3: No | T3: No | U3: Yes | V3: No | W3: No | X3: Numeric | Y3: Numeric | Z3: Decide | AA3: Shallow | AB3: Numeric | AC3: Numeric | AD3: Rule-Based | AE3: Human | AF3: No | AG3: HAI = BB-8 | AH3: No | AI3: No | AK3: Prediction Error | AL3: Error | AM3: Down | AN3: 1250 | AO3: 252 | AP3: 256 | AQ3: Crowdworkers | AR3: Crowdworkers | AS3: MTurk | AT3: No | AU3: Yes | AV3: 330555 | AW3: 180000 | AX3: 234453 | AY3: -330555 | AZ3: -180000 | BA3: -234453 | BB3: AI | BC3: -180000 | BD3: -330555 | BE3: 0 | BF3: 122515 | BG3: 0 | BH3: 77178 | BI3: 0 | BJ3: 122515 | BK3: No | BL3: HAI = BB-8
A4: Poursabzi-Sangdeh_2021 | B4: 5 | C4: 1 | D4: 3 | E4: 1 | F4: 5.1 | G4: 5.1.3.1 | H4: Manipulating and Measuring Model Interpretability | I4: Poursabzi-Sangdeh, Forough; Goldstein, Daniel G; Hofman, Jake M; Wortman Vaughan, Jennifer Wortman; Wallach, Hanna | J4: 2021 | K4: Business | L4: Proceedings of the 2021 CHI Conference on Human Factors in Computing Systems | M4: Mixed, Between-Subjects | N4: Independent Samples | O4: Predict housing prices | P4: =VLOOKUP(O4,Sheet3!$A$1:$B$22,2,0) -> Demand Forecasting | Q4: Numeric | R4: No | S4: No | T4: No | U4: Yes | V4: No | W4: No | X4: Numeric | Y4: Numeric | Z4: Decide | AA4: Shallow | AB4: Numeric | AC4: Numeric | AD4: Rule-Based | AE4: Human | AF4: No | AG4: HAI = CLEAR-2 | AH4: Yes | AI4: No | AJ4: Image, Numeric | AK4: Prediction Error | AL4: Error | AM4: Down | AN4: 1250 | AO4: 252 | AP4: 248 | AQ4: Crowdworkers | AR4: Crowdworkers | AS4: MTurk | AT4: No | AU4: Yes | AV4: 330555 | AW4: 180000 | AX4: 232943 | AY4: -330555 | AZ4: -180000 | BA4: -232943 | BB4: AI | BC4: -180000 | BD4: -330555 | BE4: 0 | BF4: 122515 | BG4: 0 | BH4: 81889 | BI4: 0 | BJ4: 122515 | BK4: No | BL4: HAI = CLEAR-2
A5: Poursabzi-Sangdeh_2021 | B5: 5 | C5: 1 | D5: 4 | E5: 1 | F5: 5.1 | G5: 5.1.4.1 | H5: Manipulating and Measuring Model Interpretability | I5: Poursabzi-Sangdeh, Forough; Goldstein, Daniel G; Hofman, Jake M; Wortman Vaughan, Jennifer Wortman; Wallach, Hanna | J5: 2021 | K5: Business | L5: Proceedings of the 2021 CHI Conference on Human Factors in Computing Systems | M5: Mixed, Between-Subjects | N5: Independent Samples | O5: Predict housing prices | P5: =VLOOKUP(O5,Sheet3!$A$1:$B$22,2,0) -> Demand Forecasting | Q5: Numeric | R5: No | S5: No | T5: No | U5: Yes | V5: No | W5: No | X5: Numeric | Y5: Numeric | Z5: Decide | AA5: Shallow | AB5: Numeric | AC5: Numeric | AD5: Rule-Based | AE5: Human | AF5: No | AG5: HAI = CLEAR-8 | AH5: Yes | AI5: No | AJ5: Image, Numeric | AK5: Prediction Error | AL5: Error | AM5: Down | AN5: 1250 | AO5: 252 | AP5: 247 | AQ5: Crowdworkers | AR5: Crowdworkers | AS5: MTurk | AT5: No | AU5: Yes | AV5: 330555 | AW5: 180000 | AX5: 248016 | AY5: -330555 | AZ5: -180000 | BA5: -248016 | BB5: AI | BC5: -180000 | BD5: -330555 | BE5: 0 | BF5: 122515 | BG5: 0 | BH5: 82411 | BI5: 0 | BJ5: 122515 | BK5: No | BL5: HAI = CLEAR-8
A6: Poursabzi-Sangdeh_2021 | B6: 5 | C6: 2 | D6: 1 | E6: 1 | F6: 5.2 | G6: 5.2.1.1 | H6: Manipulating and Measuring Model Interpretability | I6: Poursabzi-Sangdeh, Forough; Goldstein, Daniel G; Hofman, Jake M; Wortman Vaughan, Jennifer Wortman; Wallach, Hanna | J6: 2021 | K6: Business | L6: Proceedings of the 2021 CHI Conference on Human Factors in Computing Systems | M6: Mixed, Between-Subjects | N6: Independent Samples | O6: Predict housing prices | P6: =VLOOKUP(O6,Sheet3!$A$1:$B$22,2,0) -> Demand Forecasting | Q6: Numeric | R6: No | S6: No | T6: No | U6: Yes | V6: No | W6: No | X6: Numeric | Y6: Numeric | Z6: Decide | AA6: Shallow | AB6: Numeric | AC6: Numeric | AD6: Rule-Based | AE6: Human | AF6: No | AG6: HAI = BB-2 | AH6: No | AI6: No | AK6: Prediction Error | AL6: Error | AM6: Down | AN6: 750 | AO6: 152 | AP6: 147 | AQ6: Crowdworkers | AR6: Crowdworkers | AS6: MTurk | AT6: No | AU6: Yes | AV6: 31145 | AW6: 18000 | AX6: 22864 | AY6: -31145 | AZ6: -18000 | BA6: -22864 | BB6: AI | BC6: -18000 | BD6: -31145 | BE6: 0 | BF6: 11303 | BG6: 0 | BH6: 5927 | BI6: 0 | BJ6: 11303 | BK6: No | BL6: HAI = BB-2
A7: Poursabzi-Sangdeh_2021 | B7: 5 | C7: 2 | D7: 2 | E7: 1 | F7: 5.2 | G7: 5.2.2.1 | H7: Manipulating and Measuring Model Interpretability | I7: Poursabzi-Sangdeh, Forough; Goldstein, Daniel G; Hofman, Jake M; Wortman Vaughan, Jennifer Wortman; Wallach, Hanna | J7: 2021 | K7: Business | L7: Proceedings of the 2021 CHI Conference on Human Factors in Computing Systems | M7: Mixed, Between-Subjects | N7: Independent Samples | O7: Predict housing prices | P7: =VLOOKUP(O7,Sheet3!$A$1:$B$22,2,0) -> Demand Forecasting | Q7: Numeric | R7: No | S7: No | T7: No | U7: Yes | V7: No | W7: No | X7: Numeric | Y7: Numeric | Z7: Decide | AA7: Shallow | AB7: Numeric | AC7: Numeric | AD7: Rule-Based | AE7: Human | AF7: No | AG7: HAI = BB-8 | AH7: No | AI7: No | AK7: Prediction Error | AL7: Error | AM7: Down | AN7: 750 | AO7: 152 | AP7: 151 | AQ7: Crowdworkers | AR7: Crowdworkers | AS7: MTurk | AT7: No | AU7: Yes | AV7: 31145 | AW7: 18000 | AX7: 23053 | AY7: -31145 | AZ7: -18000 | BA7: -23053 | BB7: AI | BC7: -18000 | BD7: -31145 | BE7: 0 | BF7: 11303 | BG7: 0 | BH7: 6341 | BI7: 0 | BJ7: 11303 | BK7: No | BL7: HAI = BB-8
A8: Poursabzi-Sangdeh_2021 | B8: 5 | C8: 2 | D8: 3 | E8: 1 | F8: 5.2 | G8: 5.2.3.1 | H8: Manipulating and Measuring Model Interpretability | I8: Poursabzi-Sangdeh, Forough; Goldstein, Daniel G; Hofman, Jake M; Wortman Vaughan, Jennifer Wortman; Wallach, Hanna | J8: 2021 | K8: Business | L8: Proceedings of the 2021 CHI Conference on Human Factors in Computing Systems | M8: Mixed, Between-Subjects | N8: Independent Samples | O8: Predict housing prices | P8: =VLOOKUP(O8,Sheet3!$A$1:$B$22,2,0) -> Demand Forecasting | Q8: Numeric | R8: No | S8: No | T8: No | U8: Yes | V8: No | W8: No | X8: Numeric | Y8: Numeric | Z8: Decide | AA8: Shallow | AB8: Numeric | AC8: Numeric | AD8: Rule-Based | AE8: Human | AF8: No | AG8: HAI = CLEAR-2 | AH8: Yes | AI8: No | AJ8: Image, Numeric | AK8: Prediction Error | AL8: Error | AM8: Down | AN8: 750 | AO8: 152 | AP8: 150 | AQ8: Crowdworkers | AR8: Crowdworkers | AS8: MTurk | AT8: No | AU8: Yes | AV8: 31145 | AW8: 18000 | AX8: 21760 | AY8: -31145 | AZ8: -18000 | BA8: -21760 | BB8: AI | BC8: -18000 | BD8: -31145 | BE8: 0 | BF8: 11303 | BG8: 0 | BH8: 6597 | BI8: 0 | BJ8: 11303 | BK8: No | BL8: HAI = CLEAR-2
A9: Poursabzi-Sangdeh_2021 | B9: 5 | C9: 2 | D9: 4 | E9: 1 | F9: 5.2 | G9: 5.2.4.1 | H9: Manipulating and Measuring Model Interpretability | I9: Poursabzi-Sangdeh, Forough; Goldstein, Daniel G; Hofman, Jake M; Wortman Vaughan, Jennifer Wortman; Wallach, Hanna | J9: 2021 | K9: Business | L9: Proceedings of the 2021 CHI Conference on Human Factors in Computing Systems | M9: Mixed, Between-Subjects | N9: Independent Samples | O9: Predict housing prices | P9: =VLOOKUP(O9,Sheet3!$A$1:$B$22,2,0) -> Demand Forecasting | Q9: Numeric | R9: No | S9: No | T9: No | U9: Yes | V9: No | W9: No | X9: Numeric | Y9: Numeric | Z9: Decide | AA9: Shallow | AB9: Numeric | AC9: Numeric | AD9: Rule-Based | AE9: Human | AF9: No | AG9: HAI = CLEAR-8 | AH9: Yes | AI9: No | AJ9: Image, Numeric | AK9: Prediction Error | AL9: Error | AM9: Down | AN9: 750 | AO9: 152 | AP9: 150 | AQ9: Crowdworkers | AR9: Crowdworkers | AS9: MTurk | AT9: No | AU9: Yes | AV9: 31145 | AW9: 18000 | AX9: 25727 | AY9: -31145 | AZ9: -18000 | BA9: -25727 | BB9: AI | BC9: -18000 | BD9: -31145 | BE9: 0 | BF9: 11303 | BG9: 0 | BH9: 8860 | BI9: 0 | BJ9: 11303 | BK9: No | BL9: HAI = CLEAR-8
A10: Poursabzi-Sangdeh_2021 | B10: 5 | C10: 3 | D10: 1 | E10: 1 | F10: 5.3 | G10: 5.3.1.1 | H10: Manipulating and Measuring Model Interpretability | I10: Poursabzi-Sangdeh, Forough; Goldstein, Daniel G; Hofman, Jake M; Wortman Vaughan, Jennifer Wortman; Wallach, Hanna | J10: 2021 | K10: Business | L10: Proceedings of the 2021 CHI Conference on Human Factors in Computing Systems | M10: Mixed, Within-Subjects | N10: Dependent Samples | O10: Predict housing prices | P10: =VLOOKUP(O10,Sheet3!$A$1:$B$22,2,0) -> Demand Forecasting | Q10: Numeric | R10: No | S10: No | T10: No | U10: Yes | V10: No | W10: No | X10: Numeric | Y10: Numeric | Z10: Decide | AA10: Shallow | AB10: Numeric | AC10: Numeric | AD10: Rule-Based | AE10: Human | AF10: No | AG10: HAI = BB-2 | AH10: No | AI10: No | AK10: Prediction Error | AL10: Error | AM10: Down | AN10: 803 | AO10: 202 | AP10: 202 | AQ10: Crowdworkers | AR10: Crowdworkers | AS10: MTurk | AT10: No | AU10: Yes | AV10: 322426 | AW10: 180000 | AX10: 226436 | AY10: -322426 | AZ10: -180000 | BA10: -226436 | BB10: AI | BC10: -180000 | BD10: -322426 | BE10: 0 | BF10: 121858 | BG10: 0 | BH10: 77781 | BI10: 0 | BJ10: 121858 | BK10: No | BL10: HAI = BB-2
A11: Poursabzi-Sangdeh_2021 | B11: 5 | C11: 3 | D11: 2 | E11: 1 | F11: 5.3 | G11: 5.3.2.1 | H11: Manipulating and Measuring Model Interpretability | I11: Poursabzi-Sangdeh, Forough; Goldstein, Daniel G; Hofman, Jake M; Wortman Vaughan, Jennifer Wortman; Wallach, Hanna | J11: 2021 | K11: Business | L11: Proceedings of the 2021 CHI Conference on Human Factors in Computing Systems | M11: Mixed, Within-Subjects | N11: Dependent Samples | O11: Predict housing prices | P11: =VLOOKUP(O11,Sheet3!$A$1:$B$22,2,0) -> Demand Forecasting | Q11: Numeric | R11: No | S11: No | T11: No | U11: Yes | V11: No | W11: No | X11: Numeric | Y11: Numeric | Z11: Decide | AA11: Shallow | AB11: Numeric | AC11: Numeric | AD11: Rule-Based | AE11: Human | AF11: No | AG11: HAI = BB-8 | AH11: No | AI11: No | AK11: Prediction Error | AL11: Error | AM11: Down | AN11: 803 | AO11: 200 | AP11: 200 | AQ11: Crowdworkers | AR11: Crowdworkers | AS11: MTurk | AT11: No | AU11: Yes | AV11: 324141 | AW11: 180000 | AX11: 217980 | AY11: -324141 | AZ11: -180000 | BA11: -217980 | BB11: AI | BC11: -180000 | BD11: -324141 | BE11: 0 | BF11: 109289 | BG11: 0 | BH11: 64729 | BI11: 0 | BJ11: 109289 | BK11: No | BL11: HAI = BB-8
A12: Poursabzi-Sangdeh_2021 | B12: 5 | C12: 3 | D12: 3 | E12: 1 | F12: 5.3 | G12: 5.3.3.1 | H12: Manipulating and Measuring Model Interpretability | I12: Poursabzi-Sangdeh, Forough; Goldstein, Daniel G; Hofman, Jake M; Wortman Vaughan, Jennifer Wortman; Wallach, Hanna | J12: 2021 | K12: Business | L12: Proceedings of the 2021 CHI Conference on Human Factors in Computing Systems | M12: Mixed, Within-Subjects | N12: Dependent Samples | O12: Predict housing prices | P12: =VLOOKUP(O12,Sheet3!$A$1:$B$22,2,0) -> Demand Forecasting | Q12: Numeric | R12: No | S12: No | T12: No | U12: Yes | V12: No | W12: No | X12: Numeric | Y12: Numeric | Z12: Decide | AA12: Shallow | AB12: Numeric | AC12: Numeric | AD12: Rule-Based | AE12: Human | AF12: No | AG12: HAI = CLEAR-2 | AH12: Yes | AI12: No | AJ12: Image, Numeric | AK12: Prediction Error | AL12: Error | AM12: Down | AN12: 803 | AO12: 202 | AP12: 202 | AQ12: Crowdworkers | AR12: Crowdworkers | AS12: MTurk | AT12: No | AU12: Yes | AV12: 307277 | AW12: 180000 | AX12: 221535 | AY12: -307277 | AZ12: -180000 | BA12: -221535 | BB12: AI | BC12: -180000 | BD12: -307277 | BE12: 0 | BF12: 110692 | BG12: 0 | BH12: 67183 | BI12: 0 | BJ12: 110692 | BK12: No | BL12: HAI = CLEAR-2
A13: Poursabzi-Sangdeh_2021 | B13: 5 | C13: 3 | D13: 4 | E13: 1 | F13: 5.3 | G13: 5.3.4.1 | H13: Manipulating and Measuring Model Interpretability | I13: Poursabzi-Sangdeh, Forough; Goldstein, Daniel G; Hofman, Jake M; Wortman Vaughan, Jennifer Wortman; Wallach, Hanna | J13: 2021 | K13: Business | L13: Proceedings of the 2021 CHI Conference on Human Factors in Computing Systems | M13: Mixed, Within-Subjects | N13: Dependent Samples | O13: Predict housing prices | P13: =VLOOKUP(O13,Sheet3!$A$1:$B$22,2,0) -> Demand Forecasting | Q13: Numeric | R13: No | S13: No | T13: No | U13: Yes | V13: No | W13: No | X13: Numeric | Y13: Numeric | Z13: Decide | AA13: Shallow | AB13: Numeric | AC13: Numeric | AD13: Rule-Based | AE13: Human | AF13: No | AG13: HAI = CLEAR-8 | AH13: Yes | AI13: No | AJ13: Image, Numeric | AK13: Prediction Error | AL13: Error | AM13: Down | AN13: 803 | AO13: 198 | AP13: 198 | AQ13: Crowdworkers | AR13: Crowdworkers | AS13: MTurk | AT13: No | AU13: Yes | AV13: 328950 | AW13: 180000 | AX13: 220850 | AY13: -328950 | AZ13: -180000 | BA13: -220850 | BB13: AI | BC13: -180000 | BD13: -328950 | BE13: 0 | BF13: 114314 | BG13: 0 | BH13: 56335 | BI13: 0 | BJ13: 114314 | BK13: No | BL13: HAI = CLEAR-8
A14: Bansal_2021 | B14: 6 | C14: 3 | D14: 1 | E14: 1 | F14: 6.3 | G14: 6.3.1.1 | H14: Does the Whole Exceed Its Parts? The Effect of AI Explanations on Complementary Team Performance | I14: Bansal, Gagan; Wu, Tongshuang; Zhou, Joyce; Fok, Raymond; Nushi, Besmira; Kamar, Ece; Ribeiro, Marco Tulio; Weld, Daniel | J14: 2021 | K14: Business | L14: Proceedings of the 2021 CHI Conference on Human Factors in Computing Systems | M14: Between-Subjects | N14: Independent Samples | O14: Answer LSAT questions | P14: =VLOOKUP(O14,Sheet3!$A$1:$B$22,2,0) -> Customer Service | Q14: Text | R14: No | S14: No | T14: No | U14: No | V14: Yes | W14: No | X14: Categoric | Y14: Categoric | Z14: Decide | AA14: Deep | AB14: Text | AC14: Categorical | AD14: Deep | AE14: Human | AF14: No | AG14: HAI = LSAT, Conf | AH14: Yes | AI14: Yes | AJ14: Numeric | AK14: Accuracy | AL14: Accuracy | AM14: Up | AN14: 507 | AO14: 100 | AP14: 102 | AQ14: Crowdworkers | AR14: Crowdworkers | AS14: MTurk | AT14: No | AU14: Yes | AV14: 0.5815 | AW14: 0.65 | AX14: 0.698 | AY14: 0.5815 | AZ14: 0.65 | BA14: 0.698 | BB14: AI | BC14: 0.65 | BD14: 0.5815 | BE14: 1 | BF14: 0.165 | BG14: 0 | BH14: 0.1391 | BI14: 0 | BJ14: 0.165 | BK14: No | BL14: HAI = Conf
A15: Bansal_2021 | B15: 6 | C15: 3 | D15: 2 | E15: 1 | F15: 6.3 | G15: 6.3.2.1 | H15: Does the Whole Exceed Its Parts? The Effect of AI Explanations on Complementary Team Performance | I15: Bansal, Gagan; Wu, Tongshuang; Zhou, Joyce; Fok, Raymond; Nushi, Besmira; Kamar, Ece; Ribeiro, Marco Tulio; Weld, Daniel | J15: 2021 | K15: Business | L15: Proceedings of the 2021 CHI Conference on Human Factors in Computing Systems | M15: Between-Subjects | N15: Independent Samples | O15: Answer LSAT questions | P15: =VLOOKUP(O15,Sheet3!$A$1:$B$22,2,0) -> Customer Service | Q15: Text | R15: No | S15: No | T15: No | U15: No | V15: Yes | W15: No | X15: Categoric | Y15: Categoric | Z15: Decide | AA15: Deep | AB15: Text | AC15: Categorical | AD15: Deep | AE15: Human | AF15: No | AG15: HAI = LSAT, Explain-Top-1 | AH15: Yes | AI15: Yes | AJ15: Image, Numeric, Text | AK15: Accuracy | AL15: Accuracy | AM15: Up | AN15: 507 | AO15: 100 | AP15: 101 | AQ15: Crowdworkers | AR15: Crowdworkers | AS15: MTurk | AT15: No | AU15: Yes | AV15: 0.5815 | AW15: 0.65 | AX15: 0.6901 | AY15: 0.5815 | AZ15: 0.65 | BA15: 0.6901 | BB15: AI | BC15: 0.65 | BD15: 0.5815 | BE15: 1 | BF15: 0.165 | BG15: 0 | BH15: 0.1303 | BI15: 0 | BJ15: 0.165 | BK15: No | BL15: HAI = Explain-Top-1
A16: Bansal_2021 | B16: 6 | C16: 3 | D16: 3 | E16: 1 | F16: 6.3 | G16: 6.3.3.1 | H16: Does the Whole Exceed Its Parts? The Effect of AI Explanations on Complementary Team Performance | I16: Bansal, Gagan; Wu, Tongshuang; Zhou, Joyce; Fok, Raymond; Nushi, Besmira; Kamar, Ece; Ribeiro, Marco Tulio; Weld, Daniel | J16: 2021 | K16: Business | L16: Proceedings of the 2021 CHI Conference on Human Factors in Computing Systems | M16: Between-Subjects | N16: Independent Samples | O16: Answer LSAT questions | P16: =VLOOKUP(O16,Sheet3!$A$1:$B$22,2,0) -> Customer Service | Q16: Text | R16: No | S16: No | T16: No | U16: No | V16: Yes | W16: No | X16: Categoric | Y16: Categoric | Z16: Decide | AA16: Deep | AB16: Text | AC16: Categorical | AD16: Deep | AE16: Human | AF16: No | AG16: HAI = LSAT, Explain-Top-2 | AH16: Yes | AI16: Yes | AJ16: Image, Numeric, Text | AK16: Accuracy | AL16: Accuracy | AM16: Up | AN16: 507 | AO16: 100 | AP16: 103 | AQ16: Crowdworkers | AR16: Crowdworkers | AS16: MTurk | AT16: No | AU16: Yes | AV16: 0.5815 | AW16: 0.65 | AX16: 0.6816 | AY16: 0.5815 | AZ16: 0.65 | BA16: 0.6816 | BB16: AI | BC16: 0.65 | BD16: 0.5815 | BE16: 1 | BF16: 0.165 | BG16: 0 | BH16: 0.1298 | BI16: 0 | BJ16: 0.165 | BK16: No | BL16: HAI = Explain-Top-2
A17: Bansal_2021 | B17: 6 | C17: 3 | D17: 4 | E17: 1 | F17: 6.3 | G17: 6.3.4.1 | H17: Does the Whole Exceed Its Parts? The Effect of AI Explanations on Complementary Team Performance | I17: Bansal, Gagan; Wu, Tongshuang; Zhou, Joyce; Fok, Raymond; Nushi, Besmira; Kamar, Ece; Ribeiro, Marco Tulio; Weld, Daniel | J17: 2021 | K17: Business | L17: Proceedings of the 2021 CHI Conference on Human Factors in Computing Systems | M17: Between-Subjects | N17: Independent Samples | O17: Answer LSAT questions | P17: =VLOOKUP(O17,Sheet3!$A$1:$B$22,2,0) -> Customer Service | Q17: Text | R17: No | S17: No | T17: No | U17: No | V17: Yes | W17: No | X17: Categoric | Y17: Categoric | Z17: Decide | AA17: Deep | AB17: Text | AC17: Categorical | AD17: Deep | AE17: Human | AF17: No | AG17: HAI = LSAT, Adaptive | AH17: Yes | AI17: Yes | AJ17: Image, Numeric, Text | AK17: Accuracy | AL17: Accuracy | AM17: Up | AN17: 507 | AO17: 100 | AP17: 101 | AQ17: Crowdworkers | AR17: Crowdworkers | AS17: MTurk | AT17: No | AU17: Yes | AV17: 0.5815 | AW17: 0.65 | AX17: 0.701 | AY17: 0.5815 | AZ17: 0.65 | BA17: 0.701 | BB17: AI | BC17: 0.65 | BD17: 0.5815 | BE17: 1 | BF17: 0.165 | BG17: 0 | BH17: 0.1204 | BI17: 0 | BJ17: 0.165 | BK17: No | BL17: HAI = Adaptive
A18: Kyriacou_2021 | B18: 7 | C18: 1 | D18: 2 | E18: 1 | F18: 7.1 | G18: 7.1.2.1 | H18: Learning to Work in a Materials Recovery Facility: Can Humans and Machines Learn from Each Other? | I18: Kyriacou, Harrison; Ramakrishnan, Anand; Whitehill, Jacob | J18: 2021 | K18: Business | L18: LAK21: 11th International Learning Analytics and Knowledge Conference | M18: Between-Subjects | N18: Independent Samples | O18: Sort recyclables | P18: =VLOOKUP(O18,Sheet3!$A$1:$B$22,2,0) -> Review Analysis | Q18: Image | R18: No | S18: No | T18: Yes | U18: No | V18: No | W18: No | X18: Binary | Y18: Binary | Z18: Decide | AA18: Deep | AB18: Image | AC18: Image | AD18: Deep | AE18: Human | AF18: No | AG18: HAI = P-P-N, Round 2 | AH18: No | AI18: No | AK18: Score | AL18: Score | AM18: Up | AN18: 33 | AO18: 21 | AP18: 12 | AQ18: Crowdworkers | AR18: Crowdworkers | AS18: MTurk | AT18: No | AU18: Yes | AV18: 60.08 | AW18: 100 | AX18: 89.67 | AY18: 60.08 | AZ18: 100 | BA18: 89.67 | BB18: AI | BC18: 100 | BD18: 60.08 | BE18: 0 | BF18: 26.44 | BG18: 0 | BH18: 14.19 | BI18: 0 | BJ18: 26.44 | BK18: No | BL18: HAI = P-P-N, Round 2
A19: Liu_2021 | B19: 9 | C19: 2 | D19: 1 | E19: 1 | F19: 9.2 | G19: 9.2.1.1 | H19: Understanding the Effect of Out-of-Distribution Examples and Interactive Explanations on Human-AI Decision Making | I19: Liu, Han; Lai, Vivian; Tan, Chenhao | J19: 2021 | K19: Business | L19: Proc. ACM Hum.-Comput. Interact. | M19: Between-Subjects | N19: Independent Samples | O19: Predict a person's profession | P19: Customer Segmentation | Q19: Text | R19: No | S19: No | T19: No | U19: No | V19: Yes | W19: No | X19: Categoric | Y19: Categoric | Z19: Decide | AA19: Shallow | AB19: Text | AC19: Categorical | AD19: Rule-Based | AE19: Human | AF19: No | AG19: BIOS, IND, H = None/None, HAI = Static/Static | AH19: Yes | AI19: No | AJ19: Image, Numeric, Text | AK19: Accuracy | AL19: Accuracy | AM19: Up | AN19: 1296 | AO19: 216 | AP19: 216 | AQ19: Crowdworkers | AR19: Crowdworkers | AS19: MTurk | AT19: No | AU19: Yes | AV19: 0.635 | AW19: 0.841 | AX19: 0.734 | AY19: 0.635 | AZ19: 0.841 | BA19: 0.734 | BB19: AI | BC19: 0.841 | BD19: 0.635 | BE19: 0 | BF19: 0.156 | BG19: 0 | BH19: 0.134 | BI19: 0 | BJ19: 0.156 | BK19: No | BL19: WikiAttack, HAI = Predicted labels
A20: Liu_2021 | B20: 9 | C20: 2 | D20: 2 | E20: 1 | F20: 9.2 | G20: 9.2.2.1 | H20: Understanding the Effect of Out-of-Distribution Examples and Interactive Explanations on Human-AI Decision Making | I20: Liu, Han; Lai, Vivian; Tan, Chenhao | J20: 2021 | K20: Business | L20: Proc. ACM Hum.-Comput. Interact. | M20: Between-Subjects | N20: Independent Samples | O20: Predict a person's profession | P20: Customer Segmentation | Q20: Text | R20: No | S20: No | T20: No | U20: No | V20: Yes | W20: No | X20: Categoric | Y20: Categoric | Z20: Decide | AA20: Shallow | AB20: Text | AC20: Categorical | AD20: Rule-Based | AE20: Human | AF20: No | AG20: BIOS, IND, H = None/None, HAI = Inter/Inter | AH20: Yes | AI20: No | AJ20: Image, Numeric, Text | AK20: Accuracy | AL20: Accuracy | AM20: Up | AN20: 1296 | AO20: 216 | AP20: 216 | AQ20: Crowdworkers | AR20: Crowdworkers | AS20: MTurk | AT20: No | AU20: Yes | AV20: 0.635 | AW20: 0.841 | AX20: 0.724 | AY20: 0.635 | AZ20: 0.841 | BA20: 0.724 | BB20: AI | BC20: 0.841 | BD20: 0.635 | BE20: 0 | BF20: 0.156 | BG20: 0 | BH20: 0.139 | BI20: 0 | BJ20: 0.156 | BK20: No | BL20: WikiAttack, HAI = Predicted labels + local explanations
A21: Liu_2021 | B21: 9 | C21: 2 | D21: 3 | E21: 1 | F21: 9.2 | G21: 9.2.3.1 | H21: Understanding the Effect of Out-of-Distribution Examples and Interactive Explanations on Human-AI Decision Making | I21: Liu, Han; Lai, Vivian; Tan, Chenhao | J21: 2021 | K21: Business | L21: Proc. ACM Hum.-Comput. Interact. | M21: Between-Subjects | N21: Independent Samples | O21: Predict a person's profession | P21: Customer Segmentation | Q21: Text | R21: No | S21: No | T21: No | U21: No | V21: Yes | W21: No | X21: Categoric | Y21: Categoric | Z21: Decide | AA21: Shallow | AB21: Text | AC21: Categorical | AD21: Rule-Based | AE21: Human | AF21: No | AG21: BIOS, OOD, H = None/None, HAI = Static/Static | AH21: Yes | AI21: No | AJ21: Image, Numeric, Text | AK21: Accuracy | AL21: Accuracy | AM21: Up | AN21: 1296 | AO21: 216 | AP21: 216 | AQ21: Crowdworkers | AR21: Crowdworkers | AS21: MTurk | AT21: No | AU21: Yes | AV21: 0.684 | AW21: 0.766 | AX21: 0.735 | AY21: 0.684 | AZ21: 0.766 | BA21: 0.735 | BB21: AI | BC21: 0.766 | BD21: 0.684 | BE21: 0 | BF21: 0.177 | BG21: 0 | BH21: 0.102 | BI21: 0 | BJ21: 0.177 | BK21: No | BL21: WikiAttack, HAI = Predicted labels + local explanations + global explanations
A22: Liu_2021 | B22: 9 | C22: 2 | D22: 4 | E22: 1 | F22: 9.2 | G22: 9.2.4.1 | H22: Understanding the Effect of Out-of-Distribution Examples and Interactive Explanations on Human-AI Decision Making | I22: Liu, Han; Lai, Vivian; Tan, Chenhao | J22: 2021 | K22: Business | L22: Proc. ACM Hum.-Comput. Interact. | M22: Between-Subjects | N22: Independent Samples | O22: Predict a person's profession | P22: Customer Segmentation | Q22: Text | R22: No | S22: No | T22: No | U22: No | V22: Yes | W22: No | X22: Categoric | Y22: Categoric | Z22: Decide | AA22: Shallow | AB22: Text | AC22: Categorical | AD22: Rule-Based | AE22: Human | AF22: No | AG22: BIOS, OOD, H = None/None, HAI = Inter/Inter | AH22: Yes | AI22: No | AJ22: Image, Numeric, Text | AK22: Accuracy | AL22: Accuracy | AM22: Up | AN22: 1296 | AO22: 216 | AP22: 216 | AQ22: Crowdworkers | AR22: Crowdworkers | AS22: MTurk | AT22: No | AU22: Yes | AV22: 0.684 | AW22: 0.766 | AX22: 0.728 | AY22: 0.684 | AZ22: 0.766 | BA22: 0.728 | BB22: AI | BC22: 0.766 | BD22: 0.684 | BE22: 0 | BF22: 0.177 | BG22: 0 | BH22: 0.13 | BI22: 0 | BJ22: 0.177 | BK22: No | BL22: Reddit, HAI = Predicted labels
A23: Ma_2023 | B23: 14 | C23: 1 | D23: 1 | E23: 1 | F23: 14.1 | G23: 14.1.1.1 | H23: Who Should I Trust: AI or Myself? Leveraging Human and AI Correctness Likelihood to Promote Appropriate Trust in AI-Assisted Decision-Making | I23: Ma, Shuai; Lei, Ying; Wang, Xinru; Zheng, Chengbo; Shi, Chuhan; Yin, Ming; Ma, Xiaojuan | J23: 2023 | K23: Business | L23: Proceedings of the 2023 CHI Conference on Human Factors in Computing Systems | M23: Between-Subjects | N23: Independent Samples | O23: Determine if person's income exceeds $50,000 | P23: Customer Segmentation | Q23: Multiple | R23: Yes | S23: No | T23: No | U23: Yes | V23: No | W23: No | X23: Binary | Y23: Binary | Z23: Decide | AA23: Shallow | AB23: Categoric, Numeric | AC23: Numeric | AD23: Rule-Based | AE23: Human | AF23: No | AG23: HAI = AI Confidence | AH23: No | AI23: Yes | AK23: Accuracy | AL23: Accuracy | AM23: Up | AN23: 293 | AO23: 59 | AP23: 59 | AQ23: Crowdworkers | AR23: Crowdworkers | AS23: Prolific | AT23: No | AU23: Yes | AV23: 0.721 | AW23: 0.7 | AX23: 0.72 | AY23: 0.721 | AZ23: 0.7 | BA23: 0.72 | BB23: Human | BC23: 0.721 | BD23: 0.7 | BE23: 0 | BF23: 0.113 | BG23: 0 | BH23: 0.099 | BI23: 0.113 | BJ23: 0 | BK23: No | BL23: HAI = AI
A24: Ma_2023 | B24: 14 | C24: 1 | D24: 2 | E24: 1 | F24: 14.1 | G24: 14.1.2.1 | H24: Who Should I Trust: AI or Myself? Leveraging Human and AI Correctness Likelihood to Promote Appropriate Trust in AI-Assisted Decision-Making | I24: Ma, Shuai; Lei, Ying; Wang, Xinru; Zheng, Chengbo; Shi, Chuhan; Yin, Ming; Ma, Xiaojuan | J24: 2023 | K24: Business | L24: Proceedings of the 2023 CHI Conference on Human Factors in Computing Systems | M24: Between-Subjects | N24: Independent Samples | O24: Determine if person's income exceeds $50,000 | P24: Customer Segmentation | Q24: Multiple | R24: Yes | S24: No | T24: No | U24: Yes | V24: No | W24: No | X24: Binary | Y24: Binary | Z24: Decide | AA24: Shallow | AB24: Categoric, Numeric | AC24: Numeric | AD24: Rule-Based | AE24: Human | AF24: No | AG24: HAI = Direct Display | AH24: No | AI24: Yes | AK24: Accuracy | AL24: Accuracy | AM24: Up | AN24: 293 | AO24: 59 | AP24: 59 | AQ24: Crowdworkers | AR24: Crowdworkers | AS24: Prolific | AT24: No | AU24: Yes | AV24: 0.721 | AW24: 0.7 | AX24: 0.758 | AY24: 0.721 | AZ24: 0.7 | BA24: 0.758 | BB24: Human | BC24: 0.721 | BD24: 0.7 | BE24: 1 | BF24: 0.113 | BG24: 0 | BH24: 0.078 | BI24: 0.113 | BJ24: 0 | BK24: No | BL24: HAI = AI + BD
A25: Ma_2023 | B25: 14 | C25: 1 | D25: 3 | E25: 1 | F25: 14.1 | G25: 14.1.3.1 | H25: Who Should I Trust: AI or Myself? Leveraging Human and AI Correctness Likelihood to Promote Appropriate Trust in AI-Assisted Decision-Making | I25: Ma, Shuai; Lei, Ying; Wang, Xinru; Zheng, Chengbo; Shi, Chuhan; Yin, Ming; Ma, Xiaojuan | J25: 2023 | K25: Business | L25: Proceedings of the 2023 CHI Conference on Human Factors in Computing Systems | M25: Between-Subjects | N25: Independent Samples | O25: Determine if person's income exceeds $50,000 | P25: Customer Segmentation | Q25: Multiple | R25: Yes | S25: No | T25: No | U25: Yes | V25: No | W25: No | X25: Binary | Y25: Binary | Z25: Decide | AA25: Shallow | AB25: Categoric, Numeric | AC25: Numeric | AD25: Rule-Based | AE25: Human | AF25: No | AG25: HAI = Adaptive Workflow | AH25: No | AI25: Yes | AK25: Accuracy | AL25: Accuracy | AM25: Up | AN25: 293 | AO25: 59 | AP25: 56 | AQ25: Crowdworkers | AR25: Crowdworkers | AS25: Prolific | AT25: No | AU25: Yes | AV25: 0.721 | AW25: 0.7 | AX25: 0.767 | AY25: 0.721 | AZ25: 0.7 | BA25: 0.767 | BB25: Human | BC25: 0.721 | BD25: 0.7 | BE25: 1 | BF25: 0.113 | BG25: 0 | BH25: 0.085 | BI25: 0.113 | BJ25: 0 | BK25: No | BL25: HAI = AI
A26: Ma_2023 | B26: 14 | C26: 1 | D26: 4 | E26: 1 | F26: 14.1 | G26: 14.1.4.1 | H26: Who Should I Trust: AI or Myself? Leveraging Human and AI Correctness Likelihood to Promote Appropriate Trust in AI-Assisted Decision-Making | I26: Ma, Shuai; Lei, Ying; Wang, Xinru; Zheng, Chengbo; Shi, Chuhan; Yin, Ming; Ma, Xiaojuan | J26: 2023 | K26: Business | L26: Proceedings of the 2023 CHI Conference on Human Factors in Computing Systems | M26: Between-Subjects | N26: Independent Samples | O26: Determine if person's income exceeds $50,000 | P26: Customer Segmentation | Q26: Multiple | R26: Yes | S26: No | T26: No | U26: Yes | V26: No | W26: No | X26: Binary | Y26: Binary | Z26: Decide | AA26: Shallow | AB26: Categoric, Numeric | AC26: Numeric | AD26: Rule-Based | AE26: Human | AF26: No | AG26: HAI = Adaptive Recommendation | AH26: Yes | AI26: Yes | AJ26: Image, Numeric | AK26: Accuracy | AL26: Accuracy | AM26: Up | AN26: 293 | AO26: 59 | AP26: 56 | AQ26: Crowdworkers | AR26: Crowdworkers | AS26: Prolific | AT26: No | AU26: Yes | AV26: 0.721 | AW26: 0.7 | AX26: 0.754 | AY26: 0.721 | AZ26: 0.7 | BA26: 0.754 | BB26: Human | BC26: 0.721 | BD26: 0.7 | BE26: 1 | BF26: 0.113 | BG26: 0 | BH26: 0.072 | BI26: 0.113 | BJ26: 0 | BK26: No | BL26: HAI = AI + BD
A27: Lehmann_2022 | B27: 20 | C27: 1 | D27: 1 | E27: 1 | F27: 20.1 | G27: 20.1.1.1 | H27: The risk of algorithm transparency: How algorithm complexity drives the effects on the use of advice | I27: Lehmann, Cedric A.; Haubitz, Christiane B.; Fuegener, Andreas; Thonemann, Ulrich W. | J27: 2022 | K27: Business | L27: Production and Operations Management | M27: Mixed, Within-Subjects | N27: Dependent Samples | O27: Forecast demand | P27: =VLOOKUP(O27,Sheet3!$A$1:$B$22,2,0) -> Demand Forecasting | Q27: Numeric | R27: No | S27: No | T27: No | U27: Yes | V27: No | W27: No | X27: Numeric | Y27: Numeric | Z27: Decide | AA27: Shallow | AB27: Numeric | AC27: Continuous | AD27: Rule-Based | AE27: Human | AF27: No | AG27: HAI = Nontransparent | AH27: No | AI27: No | AK27: MAE | AL27: Error | AM27: Down | AN27: 509 | AO27: 171 | AP27: 171 | AQ27: Crowdworkers | AR27: Crowdworkers | AS27: MTurk | AT27: No | AU27: Yes | AV27: 179.54 | AW27: 66.2 | AX27: 111.24 | AY27: -179.54 | AZ27: -66.2 | BA27: -111.24 | BB27: AI | BC27: -66.2 | BD27: -179.54 | BE27: 0 | BF27: 47.93 | BG27: 0 | BH27: 42.24 | BI27: 0 | BJ27: 47.93 | BK27: No | BL27: H = TagLab Manual; HAI = TagLabEdit
A28: Lehmann_2022 | B28: 20 | C28: 1 | D28: 2 | E28: 1 | F28: 20.1 | G28: 20.1.2.1 | H28: The risk of algorithm transparency: How algorithm complexity drives the effects on the use of advice | I28: Lehmann, Cedric A.; Haubitz, Christiane B.; Fuegener, Andreas; Thonemann, Ulrich W. | J28: 2022 | K28: Business | L28: Production and Operations Management | M28: Mixed, Within-Subjects | N28: Dependent Samples | O28: Forecast demand | P28: =VLOOKUP(O28,Sheet3!$A$1:$B$22,2,0) -> Demand Forecasting | Q28: Numeric | R28: No | S28: No | T28: No | U28: Yes | V28: No | W28: No | X28: Numeric | Y28: Numeric | Z28: Decide | AA28: Shallow | AB28: Numeric | AC28: Continuous | AD28: Rule-Based | AE28: Human | AF28: No | AG28: HAI = Transparent-simple | AH28: Yes | AI28: No | AJ28: Numeric, Text | AK28: MAE | AL28: Error | AM28: Down | AN28: 509 | AO28: 171 | AP28: 171 | AQ28: Crowdworkers | AR28: Crowdworkers | AS28: MTurk | AT28: No | AU28: Yes | AV28: 184.04 | AW28: 66.2 | AX28: 135 | AY28: -184.04 | AZ28: -66.2 | BA28: -135 | BB28: AI | BC28: -66.2 | BD28: -184.04 | BE28: 0 | BF28: 47.29 | BG28: 0 | BH28: 55.45 | BI28: 0 | BJ28: 47.29 | BK28: No | BL28: H = TagLab Manual; HAI = TagLabAssisted
A29: Lehmann_2022 | B29: 20 | C29: 1 | D29: 3 | E29: 1 | F29: 20.1 | G29: 20.1.3.1 | H29: The risk of algorithm transparency: How algorithm complexity drives the effects on the use of advice | I29: Lehmann, Cedric A.; Haubitz, Christiane B.; Fuegener, Andreas; Thonemann, Ulrich W. | J29: 2022 | K29: Business | L29: Production and Operations Management | M29: Mixed, Within-Subjects | N29: Dependent Samples | O29: Forecast demand | P29: =VLOOKUP(O29,Sheet3!$A$1:$B$22,2,0) -> Demand Forecasting | Q29: Numeric | R29: No | S29: No | T29: No | U29: Yes | V29: No | W29: No | X29: Numeric | Y29: Numeric | Z29: Decide | AA29: Shallow | AB29: Numeric | AC29: Continuous | AD29: Rule-Based | AE29: Human | AF29: No | AG29: HAI = Transparent | AH29: Yes | AI29: No | AJ29: Image, Numeric, Text | AK29: MAE | AL29: Error | AM29: Down | AN29: 509 | AO29: 167 | AP29: 167 | AQ29: Crowdworkers | AR29: Crowdworkers | AS29: MTurk | AT29: No | AU29: Yes | AV29: 181.81 | AW29: 66.2 | AX29: 106.79 | AY29: -181.81 | AZ29: -66.2 | BA29: -106.79 | BB29: AI | BC29: -66.2 | BD29: -181.81 | BE29: 0 | BF29: 43.61 | BG29: 0 | BH29: 42.9 | BI29: 0 | BJ29: 43.61 | BK29: No | BL29: H = TagLab Manual; HAI = TagLabEdit
A30: Skirzynski_2021 | B30: 27 | C30: 1 | D30: 1 | E30: 1 | F30: 27.1 | G30: 27.1.1.1 | H30: Automatic discovery of interpretable planning strategies | I30: Skirzynski, J; Becker, F; Lieder, F | J30: 2021 | K30: Business | L30: Machine Learning | M30: Between-Subjects | N30: Independent Samples | O30: Plan a route | P30: =VLOOKUP(O30,Sheet3!$A$1:$B$22,2,0) -> Demand Forecasting | Q30: Numeric | R30: No | S30: No | T30: No | U30: Yes | V30: No | W30: No | X30: Categoric | Y30: Categoric | Z30: Decide | AA30: Shallow | AB30: Numeric | AC30: Categorical | AD30: Rule-Based | AE30: Human | AF30: No | AG30: Increasing Variance | AH30: Yes | AI30: No | AJ30: Image, Text | AK30: Expected Score | AL30: Score | AM30: Up | AN30: 236 | AO30: 78 | AP30: 79 | AQ30: Crowdworkers | AR30: Crowdworkers | AS30: MTurk | AT30: No | AU30: Yes | AV30: 28.41 | AW30: 39.17 | AX30: 34.47 | AY30: 28.41 | AZ30: 39.17 | BA30: 34.47 | BB30: AI | BC30: 39.17 | BD30: 28.41 | BE30: 0 | BF30: 13.33 | BG30: 0 | BH30: 11.85 | BI30: 0 | BJ30: 13.33 | BK30: No | BL30: AI-FHD(Higher)
A31: Skirzynski_2021 | B31: 27 | C31: 2 | D31: 1 | E31: 1 | F31: 27.2 | G31: 27.2.1.1 | H31: Automatic discovery of interpretable planning strategies | I31: Skirzynski, J; Becker, F; Lieder, F | J31: 2021 | K31: Business | L31: Machine Learning | M31: Between-Subjects | N31: Independent Samples | O31: Plan a route | P31: =VLOOKUP(O31,Sheet3!$A$1:$B$22,2,0) -> Demand Forecasting | Q31: Numeric | R31: No | S31: No | T31: No | U31: Yes | V31: No | W31: No | X31: Categoric | Y31: Categoric | Z31: Decide | AA31: Shallow | AB31: Numeric | AC31: Categorical | AD31: Rule-Based | AE31: Human | AF31: No | AG31: Decreasing Variance | AH31: Yes | AI31: No | AJ31: Image, Text | AK31: Expected Score | AL31: Score | AM31: Up | AN31: 222 | AO31: 70 | AP31: 76 | AQ31: Crowdworkers | AR31: Crowdworkers | AS31: MTurk | AT31: No | AU31: Yes | AV31: 22.75 | AW31: 28.47 | AX31: 24.02 | AY31: 22.75 | AZ31: 28.47 | BA31: 24.02 | BB31: AI | BC31: 28.47 | BD31: 22.75 | BE31: 0 | BF31: 8.18 | BG31: 0 | BH31: 7.38 | BI31: 0 | BJ31: 8.18 | BK31: No | BL31: AI-XAI-FHD(Lower)
A32: Skirzynski_2021 | B32: 27 | C32: 3 | D32: 1 | E32: 1 | F32: 27.3 | G32: 27.3.1.1 | H32: Automatic discovery of interpretable planning strategies | I32: Skirzynski, J; Becker, F; Lieder, F | J32: 2021 | K32: Business | L32: Machine Learning | M32: Between-Subjects | N32: Independent Samples | O32: Plan a route | P32: =VLOOKUP(O32,Sheet3!$A$1:$B$22,2,0) -> Demand Forecasting | Q32: Numeric | R32: No | S32: No | T32: No | U32: Yes | V32: No | W32: No | X32: Categoric | Y32: Categoric | Z32: Decide | AA32: Shallow | AB32: Numeric | AC32: Categorical | AD32: Rule-Based | AE32: Human | AF32: No | AG32: Constant Variance | AH32: Yes | AI32: No | AJ32: Image, Text | AK32: Expected Score | AL32: Score | AM32: Up | AN32: 178 | AO32: 60 | AP32: 59 | AQ32: Crowdworkers | AR32: Crowdworkers | AS32: MTurk | AT32: No | AU32: Yes | AV32: 4.17 | AW32: 7.03 | AX32: 5.95 | AY32: 4.17 | AZ32: 7.03 | BA32: 5.95 | BB32: AI | BC32: 7.03 | BD32: 4.17 | BE32: 0 | BF32: 2.63 | BG32: 0 | BH32: 2.75 | BI32: 0 | BJ32: 2.63 | BK32: No | BL32: AI-XAI-FHD(Higher)
A33: Hemmer_2022 | B33: 68 | C33: 1 | D33: 2 | E33: 1 | F33: 68.1 | G33: 68.1.2.1 | H33: On the effect of information asymmetry in human-AI teams | I33: Hemmer, Patrick; Schemmer, Max; KÃ¼hl, Niklas; VÃ¶ssing, Michael; Satzger, Gerhard | J33: 2022 | K33: Business | L33: CHI Conference on Human Factors in Computing Systems (CHI '22), Workshop on Human-Centered Explainable AI (HCXAI) | M33: Between-Subjects | N33: Independent Samples | O33: Predict housing prices | P33: =VLOOKUP(O33,Sheet3!$A$1:$B$22,2,0) -> Demand Forecasting | Q33: Multiple | R33: Yes | S33: No | T33: No | U33: Yes | V33: No | W33: No | X33: Numeric | Y33: Numeric | Z33: Decide | AA33: Shallow | AB33: Categoric, Numeric | AC33: Continuous | AD33: Rule-Based | AE33: Human | AF33: No | AG33: UHCI | AH33: No | AI33: Yes | AK33: MAE | AL33: Error | AM33: Down | AN33: 154 | AO33: 48 | AP33: 48 | AQ33: Crowdworkers | AR33: Crowdworkers | AS33: Prolific | AT33: No | AU33: Yes | AV33: 200510 | AW33: 163080 | AX33: 148009 | AY33: -200510 | AZ33: -163080 | BA33: -148009 | BB33: AI | BC33: -163080 | BD33: -200510 | BE33: 1 | BF33: 45348 | BG33: 0 | BH33: 22079 | BI33: 0 | BJ33: 45348 | BK33: No | BL33: Concurrent, AI, HAI = B, Noise = 125
A34: Chen_2023 | B34: 69 | C34: 1 | D34: 1 | E34: 1 | F34: 69.1 | G34: 69.1.1.1 | H34: Understanding the role of human intuition on reliance in human-AI decision-making with explanations | I34: Chen, Valerie; Liao, Q. Vera; Vaughan, Jennifer Wortman; Bansal, Gagan | J34: 2023 | K34: Business | L34: CSCW 2023 | M34: Within-Subjects | N34: Dependent Samples | O34: Predict housing prices | P34: =VLOOKUP(O34,Sheet3!$A$1:$B$22,2,0) -> Demand Forecasting | Q34: Multiple | R34: Yes | S34: No | T34: No | U34: Yes | V34: No | W34: No | X34: Binary | Y34: Binary | Z34: Decide | AA34: Shallow | AB34: Categoric, Numeric | AC34: Binary | AD34: Rule-Based | AE34: Human | AF34: No | AG34: HAI = Feature-Based | AH34: Yes | AI34: No | AJ34: Image, Numeric | AK34: Accuracy | AL34: Accuracy | AM34: Up | AN34: 13 | AO34: 13 | AP34: 13 | AQ34: Volunteers | AR34: Volunteers | AS34: Email, Twitter | AT34: No | AU34: No | AV34: 0.611 | AW34: 0.625 | AX34: 0.606 | AY34: 0.611 | AZ34: 0.625 | BA34: 0.606 | BB34: AI | BC34: 0.625 | BD34: 0.611 | BE34: 0 | BF34: 0.1046 | BG34: 0 | BH34: 0.1514 | BI34: 0 | BJ34: 0.1046 | BK34: No | BL34: Concurrent, AI, HAI = B, Noise = 140
A35: Chen_2023 | B35: 69 | C35: 1 | D35: 2 | E35: 1 | F35: 69.1 | G35: 69.1.2.1 | H35: Understanding the role of human intuition on reliance in human-AI decision-making with explanations | I35: Chen, Valerie; Liao, Q. Vera; Vaughan, Jennifer Wortman; Bansal, Gagan | J35: 2023 | K35: Business | L35: CSCW 2023 | M35: Within-Subjects | N35: Dependent Samples | O35: Predict housing prices | P35: =VLOOKUP(O35,Sheet3!$A$1:$B$22,2,0) -> Demand Forecasting | Q35: Multiple | R35: Yes | S35: No | T35: No | U35: Yes | V35: No | W35: No | X35: Binary | Y35: Binary | Z35: Decide | AA35: Shallow | AB35: Categoric, Numeric | AC35: Binary | AD35: Rule-Based | AE35: Human | AF35: No | AG35: HAI = Example-Based | AH35: Yes | AI35: No | AJ35: Image, Numeric, Text | AK35: Accuracy | AL35: Accuracy | AM35: Up | AN35: 13 | AO35: 13 | AP35: 13 | AQ35: Volunteers | AR35: Volunteers | AS35: Email, Twitter | AT35: No | AU35: No | AV35: 0.611 | AW35: 0.625 | AX35: 0.711 | AY35: 0.611 | AZ35: 0.625 | BA35: 0.711 | BB35: AI | BC35: 0.625 | BD35: 0.611 | BE35: 1 | BF35: 0.1046 | BG35: 0 | BH35: 0.1046 | BI35: 0 | BJ35: 0.1046 | BK35: No | BL35: Concurrent, AI, HAI = B, Noise = 155
A36: Chen_2023 | B36: 69 | C36: 2 | D36: 1 | E36: 1 | F36: 69.2 | G36: 69.2.1.1 | H36: Understanding the role of human intuition on reliance in human-AI decision-making with explanations | I36: Chen, Valerie; Liao, Q. Vera; Vaughan, Jennifer Wortman; Bansal, Gagan | J36: 2023 | K36: Business | L36: CSCW 2023 | M36: Within-Subjects | N36: Dependent Samples | O36: Predict housing prices | P36: =VLOOKUP(O36,Sheet3!$A$1:$B$22,2,0) -> Demand Forecasting | Q36: Multiple | R36: Yes | S36: No | T36: No | U36: Yes | V36: No | W36: No | X36: Categoric | Y36: Categoric | Z36: Decide | AA36: Shallow | AB36: Categoric, Numeric | AC36: Categorical | AD36: Rule-Based | AE36: Human | AF36: No | AG36: HAI = Feature-Based | AH36: Yes | AI36: No | AJ36: Image, Numeric | AK36: Accuracy | AL36: Accuracy | AM36: Up | AN36: 13 | AO36: 13 | AP36: 13 | AQ36: Volunteers | AR36: Volunteers | AS36: Email, Twitter | AT36: No | AU36: No | AV36: 0.6 | AW36: 0.625 | AX36: 0.644 | AY36: 0.6 | AZ36: 0.625 | BA36: 0.644 | BB36: AI | BC36: 0.625 | BD36: 0.6 | BE36: 1 | BF36: 0.1586 | BG36: 0 | BH36: 0.155 | BI36: 0 | BJ36: 0.1586 | BK36: No | BL36: Concurrent, AI, HAI = B, Noise = 170
A37: Chen_2023 | B37: 69 | C37: 2 | D37: 2 | E37: 1 | F37: 69.2 | G37: 69.2.2.1 | H37: Understanding the role of human intuition on reliance in human-AI decision-making with explanations | I37: Chen, Valerie; Liao, Q. Vera; Vaughan, Jennifer Wortman; Bansal, Gagan | J37: 2023 | K37: Business | L37: CSCW 2023 | M37: Within-Subjects | N37: Dependent Samples | O37: Predict a person's profession | P37: Customer Segmentation | Q37: Multiple | R37: Yes | S37: No | T37: No | U37: Yes | V37: No | W37: No | X37: Categoric | Y37: Categoric | Z37: Decide | AA37: Shallow | AB37: Categoric, Numeric | AC37: Categorical | AD37: Rule-Based | AE37: Human | AF37: No | AG37: HAI = Example-Based | AH37: Yes | AI37: No | AJ37: Image, Numeric, Text | AK37: Accuracy | AL37: Accuracy | AM37: Up | AN37: 13 | AO37: 13 | AP37: 13 | AQ37: Volunteers | AR37: Volunteers | AS37: Email, Twitter | AT37: No | AU37: No | AV37: 0.6 | AW37: 0.625 | AX37: 0.712 | AY37: 0.6 | AZ37: 0.625 | BA37: 0.712 | BB37: AI | BC37: 0.625 | BD37: 0.6 | BE37: 1 | BF37: 0.1586 | BG37: 0 | BH37: 0.1659 | BI37: 0 | BJ37: 0.1586 | BK37: No | BL37: Concurrent, AI, HAI = C, Noise = 0
A38: Elder_2022 | B38: 72 | C38: 1 | D38: 1 | E38: 1 | F38: 72.1 | G38: 72.1.1.1 | H38: Knowing when to pass: The effect of AI reliability in risky decision contexts | I38: Elder, Hannah; Canfield, Casey; Shank, Daniel B.; Rieger, Tobias; Hines, Casey | J38: 2022 | K38: Business | L38: Human Factors | M38: Between-Subjects | N38: Independent Samples | O38: Predict basketball games | P38: =VLOOKUP(O38,Sheet3!$A$1:$B$22,2,0) -> Demand Forecasting | Q38: Numeric | R38: No | S38: No | T38: No | U38: Yes | V38: No | W38: No | X38: Binary | Y38: Binary | Z38: Decide | AA38: Wizard of Oz | AB38: Numeric | AC38: Binary | AD38: Simulated-AI | AE38: Human | AF38: No | AG38: Low Acc | AH38: No | AI38: No | AK38: Accuracy | AL38: Accuracy | AM38: Up | AN38: 245 | AO38: 81 | AP38: 82 | AQ38: Crowdworkers | AR38: Crowdworkers | AS38: Prolific | AT38: No | AU38: Yes | AV38: 0.52 | AW38: 0.6 | AX38: 0.57 | AY38: 0.52 | AZ38: 0.6 | BA38: 0.57 | BB38: AI | BC38: 0.6 | BD38: 0.52 | BE38: 0 | BF38: 0.09 | BG38: 0 | BH38: 0.1 | BI38: 0 | BJ38: 0.09 | BK38: No
A39: Elder_2022 | B39: 72 | C39: 1 | D39: 1 | E39: 2 | F39: 72.1 | G39: 72.1.1.2 | H39: Knowing when to pass: The effect of AI reliability in risky decision contexts | I39: Elder, Hannah; Canfield, Casey; Shank, Daniel B.; Rieger, Tobias; Hines, Casey | J39: 2022 | K39: Business | L39: Human Factors | M39: Between-Subjects | N39: Independent Samples | O39: Predict basketball games | P39: =VLOOKUP(O39,Sheet3!$A$1:$B$22,2,0) -> Demand Forecasting | Q39: Numeric | R39: No | S39: No | T39: No | U39: Yes | V39: No | W39: No | X39: Binary | Y39: Binary | Z39: Decide | AA39: Wizard of Oz | AB39: Numeric | AC39: Binary | AD39: Simulated-AI | AE39: Human | AF39: No | AG39: Low Acc | AH39: No | AI39: No | AK39: Sensitivity (d') | AL39: Error Rate | AM39: Up | AN39: 245 | AO39: 81 | AP39: 82 | AQ39: Crowdworkers | AR39: Crowdworkers | AS39: Prolific | AT39: No | AU39: Yes | AV39: -0.08 | AW39: 0.76 | AX39: 0.22 | AY39: -0.08 | AZ39: 0.76 | BA39: 0.22 | BB39: AI | BC39: 0.76 | BD39: -0.08 | BE39: 0 | BF39: 0.5 | BG39: 0 | BH39: 0.59 | BI39: 0 | BJ39: 0.5 | BK39: No
A40: Elder_2022 | B40: 72 | C40: 1 | D40: 1 | E40: 3 | F40: 72.1 | G40: 72.1.1.3 | H40: Knowing when to pass: The effect of AI reliability in risky decision contexts | I40: Elder, Hannah; Canfield, Casey; Shank, Daniel B.; Rieger, Tobias; Hines, Casey | J40: 2022 | K40: Business | L40: Human Factors | M40: Between-Subjects | N40: Independent Samples | O40: Predict basketball games | P40: =VLOOKUP(O40,Sheet3!$A$1:$B$22,2,0) -> Demand Forecasting | Q40: Numeric | R40: No | S40: No | T40: No | U40: Yes | V40: No | W40: No | X40: Binary | Y40: Binary | Z40: Decide | AA40: Wizard of Oz | AB40: Numeric | AC40: Binary | AD40: Simulated-AI | AE40: Human | AF40: No | AG40: Low Acc | AH40: No | AI40: No | AK40: Response Bias | AL40: Error Rate | AM40: Down | AN40: 245 | AO40: 81 | AP40: 82 | AQ40: Crowdworkers | AR40: Crowdworkers | AS40: Prolific | AT40: No | AU40: Yes | AV40: 0.33 | AW40: 0.9 | AX40: 0.41 | AY40: 0.33 | AZ40: 0.9 | BA40: 0.41 | BB40: AI | BC40: 0.9 | BD40: 0.33 | BE40: 0 | BF40: 0.44 | BG40: 0 | BH40: 0.49 | BI40: 0 | BJ40: 0.44 | BK40: No
...

Sheet Sheet3
A1: Task_Desc | B1: Marketing-Related Task Category
A2: Predict housing prices | B2: Demand Forecasting
A3: Forecast demand | B3: Demand Forecasting
A4: Plan a route | B4: Demand Forecasting
A5: Predict basketball games | B5: Demand Forecasting
A6: Predicting behavioral science study outcomes | B6: Demand Forecasting
A7: Predict a person’s profession | B7: Customer Segmentation
A8: Determine if person’s income exceeds $50,000 | B8: Customer Segmentation
A9: Sort recyclables | B9: Review Analysis
A10: Classify toxic comments | B10: Review Analysis
A11: Classify beer reviews | B11: Review Analysis
A12: Classify Amazon reviews | B12: Review Analysis
... A22: Answer LSAT questions | B22: Customer Service

Sheet Sheet2
A3: Row Labels | B3: Count of Title | F3: Paper_Name | G3: =VLOOKUP(F3,$A$4:$B$31,2,0) -> #N/A
A4: Bansal_2021 | B4: 12 | F4: Poursabzi-Sangdeh_2021 | G4: =VLOOKUP(F4,$A$4:$B$31,2,0) -> 12
A5: Bondi_2022 | B5: 3 | F5: Bansal_2021 | G5: =VLOOKUP(F5,$A$4:$B$31,2,0) -> 12
A6: Cabrera_2023 | B6: 2 | F6: Kyriacou_2021 | G6: =VLOOKUP(F6,$A$4:$B$31,2,0) -> 1
A7: Carton_2020 | B7: 15 | F7: Liu_2021 | G7: =VLOOKUP(F7,$A$4:$B$31,2,0) -> 4
A8: Chen_2023 | B8: 4 | F8: Ma_2023 | G8: =VLOOKUP(F8,$A$4:$B$31,2,0) -> 4
A9: Desmond_2021 | B9: 2 | F9: Lehmann_2022 | G9: =VLOOKUP(F9,$A$4:$B$31,2,0) -> 3
A10: Elder_2022 | B10: 6 | F10: Skirzynski_2021 | G10: =VLOOKUP(F10,$A$4:$B$31,2,0) -> 3
A11: Gao_2021 | B11: 4 | F11: Hemmer_2022 | G11: =VLOOKUP(F11,$A$4:$B$31,2,0) -> 1
A12: Groh_2022 | B12: 2 | F12: Chen_2023 | G12: =VLOOKUP(F12,$A$4:$B$31,2,0) -> 4
A13: Hemmer_2022 | B13: 1 | F13: Elder_2022 | G13: =VLOOKUP(F13,$A$4:$B$31,2,0) -> 6
A14: Jiang_2020 | B14: 6 | F14: Bondi_2022 | G14: =VLOOKUP(F14,$A$4:$B$31,2,0) -> 3
A15: Kyriacou_2021 | B15: 1 | F15: Lu_Peng_2024 | G15: =VLOOKUP(F15,$A$4:$B$31,2,0) -> 1
... A30: Vodrahalli_2022 | B30: 5 | F30: Vodrahalli_2022 | G30: =VLOOKUP(F30,$A$4:$B$31,2,0) -> 5
A31: (blank)
A32: Grand Total | B32: 132

Sheet Sheet1
A1: Paper_Name | B1: Paper_ID | C1: Exp_ID | D1: Treatment_ID | E1: Measure_ID | F1: Exp_ID_Cleaned | G1: ES_ID | H1: Title | I1: Authors | J1: Year | K1: Venue | L1: Exp_Design | M1: Comp_Type | N1: Task_Desc | O1: Task_Data | P1: Task_Data_Cleaned
A2: Poursabzi-Sangdeh_2021 | B2: 5 | C2: 1 | D2: 1 | E2: 1 | F2: 5.1 | G2: 5.1.1.1 | H2: Manipulating and Measuring Model Interpretability | I2: Poursabzi-Sangdeh, Forough; Goldstein, Daniel G; Hofman, Jake M; Wortman Vaughan, Jennifer Wortman; Wallach, Hanna | J2: 2021 | K2: Proceedings of the 2021 CHI Conference on Human Factors in Computing Systems | L2: Mixed, Between-Subjects | M2: Independent Samples | N2: Predict housing prices | O2: Numeric | P2: Numeric
A3: Bansal_2021 | B3: 6 | C3: 3 | D3: 1 | E3: 1 | F3: 6.3 | G3: 6.3.1.1 | H3: Does the Whole Exceed Its Parts? The Effect of AI Explanations on Complementary Team Performance | I3: Bansal, Gagan; Wu, Tongshuang; Zhou, Joyce; Fok, Raymond; Nushi, Besmira; Kamar, Ece; Ribeiro, Marco Tulio; Weld, Daniel | J3: 2021 | K3: Proceedings of the 2021 CHI Conference on Human Factors in Computing Systems | L3: Between-Subjects | M3: Independent Samples | N3: Answer LSAT questions | O3: Text | P3: Text
A4: Kyriacou_2021 | B4: 7 | C4: 1 | D4: 2 | E4: 1 | F4: 7.1 | G4: 7.1.2.1 | H4: Learning to Work in a Materials Recovery Facility: Can Humans and Machines Learn from Each Other? | I4: Kyriacou, Harrison; Ramakrishnan, Anand; Whitehill, Jacob | J4: 2021 | K4: LAK21: 11th International Learning Analytics and Knowledge Conference | L4: Between-Subjects | M4: Independent Samples | N4: Sort recyclables | O4: Image | P4: Image
A5: Liu_2021 | B5: 9 | C5: 2 | D5: 1 | E5: 1 | F5: 9.2 | G5: 9.2.1.1 | H5: Understanding the Effect of Out-of-Distribution Examples and Interactive Explanations on Human-AI Decision Making | I5: Liu, Han; Lai, Vivian; Tan, Chenhao | J5: 2021 | K5: Proc. ACM Hum.-Comput. Interact. | L5: Between-Subjects | M5: Independent Samples | N5: Predict a person's profession | O5: Text | P5: Text
A6: Ma_2023 | B6: 14 | C6: 1 | D6: 1 | E6: 1 | F6: 14.1 | G6: 14.1.1.1 | H6: Who Should I Trust: AI or Myself? Leveraging Human and AI Correctness Likelihood to Promote Appropriate Trust in AI-Assisted Decision-Making | I6: Ma, Shuai; Lei, Ying; Wang, Xinru; Zheng, Chengbo; Shi, Chuhan; Yin, Ming; Ma, Xiaojuan | J6: 2023 | K6: Proceedings of the 2023 CHI Conference on Human Factors in Computing Systems | L6: Between-Subjects | M6: Independent Samples | N6: Determine if person's income exceeds $50,000 | O6: Categoric, Numeric | P6: Multiple
A7: Lehmann_2022 | B7: 20 | C7: 1 | D7: 1 | E7: 1 | F7: 20.1 | G7: 20.1.1.1 | H7: The risk of algorithm transparency: How algorithm complexity drives the effects on the use of advice | I7: Lehmann, Cedric A.; Haubitz, Christiane B.; Fuegener, Andreas; Thonemann, Ulrich W. | J7: 2022 | K7: Production and Operations Management | L7: Mixed, Within-Subjects | M7: Dependent Samples | N7: Forecast demand | O7: Numeric | P7: Numeric
A8: Skirzynski_2021 | B8: 27 | C8: 1 | D8: 1 | E8: 1 | F8: 27.1 | G8: 27.1.1.1 | H8: Automatic discovery of interpretable planning strategies | I8: Skirzynski, J; Becker, F; Lieder, F | J8: 2021 | K8: Machine Learning | L8: Between-Subjects | M8: Independent Samples | N8: Plan a route | O8: Numeric | P8: Numeric
A9: Hemmer_2022 | B9: 68 | C9: 1 | D9: 2 | E9: 1 | F9: 68.1 | G9: 68.1.2.1 | H9: On the effect of information asymmetry in human-AI teams | I9: Hemmer, Patrick; Schemmer, Max; KÃ¼hl, Niklas; VÃ¶ssing, Michael; Satzger, Gerhard | J9: 2022 | K9: CHI Conference on Human Factors in Computing Systems (CHI â€™22), Workshop on Human-Centered Explainable AI (HCXAI) | L9: Between-Subjects | M9: Independent Samples | N9: Predict housing prices | O9: Categoric, Numeric | P9: Multiple
A10: Chen_2023 | B10: 69 | C10: 1 | D10: 1 | E10: 1 | F10: 69.1 | G10: 69.1.1.1 | H10: Understanding the role of human intuition on reliance in human-AI decision-making with explanations | I10: Chen, Valerie; Liao, Q. Vera; Vaughan, Jennifer Wortman; Bansal, Gagan | J10: 2023 | K10: CSCW 2023 | L10: Within-Subjects | M10: Dependent Samples | N10: Predict housing prices | O10: Categoric, Numeric | P10: Multiple
A11: Elder_2022 | B11: 72 | C11: 1 | D11: 1 | E11: 1 | F11: 72.1 | G11: 72.1.1.1 | H11: Knowing when to pass: The effect of AI reliability in risky decision contexts | I11: Elder, Hannah; Canfield, Casey; Shank, Daniel B.; Rieger, Tobias; Hines, Casey | J11: 2022 | K11: Human Factors | L11: Between-Subjects | M11: Independent Samples | N11: Predict basketball games | O11: Numeric | P11: Numeric
A12: Bondi_2022 | B12: 74 | C12: 1 | D12: 1 | E12: 1 | F12: 74.1 | G12: 74.1.1.1 | H12: Role of human-AI interaction in selective prediction | I12: Bondi, Elizabeth; Koster, Raphael; Sheahan, Hannah; Chadwick, Martin; Bachrach, Yoram; Cemgil, Taylan; Paquet, Ulrich; Dvijotham, Krishnamurthy | J12: 2022 | K12: Proceedings of the AAAI Conference on Artificial Intelligence | L12: Within-Subjects | M12: Dependent Samples | N12: Detect animal in image | O12: Image | P12: Image
A13: Lu_Peng_2024 | B13: 84 | C13: 4 | D13: 1 | E13: 1 | F13: 4.1 | G13: Lu_Peng_2024_1 | H13: Human-AI Collaboration: Unraveling the Effects of User Proficiency and AI Agent Capability in Intelligent Decision Support Systems | I13: Lu Peng, Xiangbin Yan, Yunan Hu, Xin Luo | J13: 2024 | K13: Decision Support Systems | L13: Between-subjects | M13: Dependent Samples | N13: Decision-making accuracy in an AI-assisted decision support system | O13: Text | P13: Image
... A27: Lippert_2024 | B27: 81 | C27: 1 | D27: 1 | E27: 1 | F27: 1.1 | G27: Lippert_2024_1 | H27: Can Large Language Models Help Predict Results from a Complex Behavioural Science Study? | I27: Lippert, Steffen; Dreber, Anna; Johannesson, Magnus; Tierney, Warren; Cyrus-Lai, Wilson; Uhlmann, Eric Luis; Pfeiffer, Thomas | J27: 2024 | K27: Royal Society Open Science | L27: Between-subjects | M27: Dependent Samples | N27: Predicting behavioral science study outcomes | O27: Text | P27: Text
A28: Vodrahalli_2022 | B28: 67 | C28: 1 | D28: 1 | E28: 1 | F28: 67.1 | G28: 79.1.1.1 | H28: Do humans trust advice more if it comes from AI? An analysis of human-AI interactions | I28: Vodrahalli, Kailas; Daneshjou, Roxana; Gerstenberg, Tobias; Zou, James | J28: 2022 | L28: Within-Subjects | M28: Dependent Samples | O28: Image | P28: Image
